<?xml version="1.0" encoding="utf-8"?>
<!-- This URDF was automatically created by SolidWorks to URDF Exporter! Originally created by Stephen Brawner (brawner@gmail.com) 
     Commit Version: 1.6.0-4-g7f85cfe  Build Version: 1.6.7995.38578
     For more information, please see http://wiki.ros.org/sw_urdf_exporter -->
<robot name="Quadruped_2">
 <material name="black">
    <color rgba="0.0 0.0 0.0 1.0"/>
  </material>
  <material name="blue">
    <color rgba="0.0 0.0 0.8 1.0"/>
  </material>
  <material name="green">
    <color rgba="0.0 0.8 0.0 1.0"/>
  </material>
  <material name="grey">
    <color rgba="0.2 0.2 0.2 1.0"/>
  </material>
  <material name="silver">
    <color rgba="0.913725490196 0.913725490196 0.847058823529 1.0"/>
  </material>
  <material name="orange">
    <!-- <color rgba="1.0 0.423529411765 0.0392156862745 1.0"/> -->
    <color rgba="0.12 0.15 0.2 1.0"/>
  </material>
  <material name="brown">
    <color rgba="0.870588235294 0.811764705882 0.764705882353 1.0"/>
  </material>
  <material name="red">
    <color rgba="0.8 0.0 0.0 1.0"/>
  </material>
  <material name="white">
    <color rgba="1.0 1.0 1.0 1.0"/>
  </material>
# base
  <link name="base">
    <visual>
      <origin xyz="0 0 0" rpy="0 0 0" />
      <geometry> 
        <mesh filename="../meshes/base.stl" scale="1 1 1"/>
      </geometry>
    </visual>
  </link>
  # base joint
  <joint name="floating_base" type="fixed">
    <origin rpy="0 0 0" xyz="0 0 0"/>
    <parent link="base"/>
    <child link="trunk"/>
  </joint>
# trunk    
  <link name="trunk">
    <visual>
      <origin xyz="0 0 0" rpy="0 0 0" />
      <geometry> 
        <mesh filename="../meshes/trunk.stl" scale="1 1 1"/>
      </geometry>
      <material name="orange"/> 
    </visual>
    # trunk_collision
    <collision>
      <origin xyz="0 0 0" rpy="0 0 0" />
      <geometry> 
        <box size="0.117 0.160 0.103"/>
      </geometry>
    </collision>
  # trunk_inertial
    <inertial>
      <origin xyz="0.00077758 -5.5511E-17 3.4694E-18" rpy="0 0 0" />
      <mass value="0.35" />
      <inertia ixx="6.177E-05" ixy="-7.1998E-21" ixz="3.359E-21" iyy="7.8861E-05" iyz="2.8572E-23" izz="0.00011694" />
    </inertial>
  </link>
  # trunk_joint
  <joint name="imu_joint" type="fixed">
    <parent link="trunk" />
    <child link="imu_link" />
    <origin xyz="0 0 0" rpy="0 0 0" />
  </joint>
# imu
  <link name="imu_link">
    <inertial>
      <mass value="0.001"/>
      <origin rpy="0 0 0" xyz="0 0 0"/>
      <inertia ixx="0.0001" ixy="0" ixz="0" iyy="0.0001" iyz="0" izz="0.0001"/>
    </inertial>
    <visual>
      <origin rpy="0 0 0" xyz="0 0 0"/>
      <geometry>
        <box size="0.001 0.001 0.001"/>
      </geometry>
      <material name="red"/>
    </visual>
    <!-- <collision>
      <origin rpy="0 0 0" xyz="0 0 0"/>
      <geometry>
        <box size=".001 .001 .001"/>
      </geometry>
    </collision> -->
  </link>
  # FR_hip_joint
  <joint name="FR_hip_joint" type="revolute">
    <origin xyz="-0.05 -0.06675 0" rpy="0 0 3.1416" />
    <parent link="trunk" />
    <child link="FR_hip" />
    <axis xyz="0 1 0" />
    <dynamics damping="0" friction="0"/>    
    <limit effort="20" lower="-1.0471975511" upper="1.0471975511" velocity="52.4" />
  </joint>
# FR_hip
  <link name="FR_hip">
    <inertial>
      <origin xyz="0.0030458 0.024513 8.3928E-05" rpy="0 0 0" />
      <mass value="0.2" />
      <inertia ixx="1.9723E-05" ixy="-7.0366E-07" ixz="-2.6212E-07" iyy="1.5442E-05" iyz="-1.9389E-08" izz="2.9228E-05" />
    </inertial>
    <visual>
      <origin xyz="0 0 0" rpy="0 0 0" />
      <geometry> 
        <mesh filename="../meshes/FR_hip.stl" scale="1 1 1"/>
      </geometry>
      <material name=""> 
        <color   rgba="0 1 1 1" />
      </material>
    </visual>
    <!-- <collision>
      <origin xyz="0 0 0" rpy="0 0 0" />
      <geometry> 
        <box size='0.061 0.042 0.0204'/> -->
      <!-- </geometry>
    </collision> -->
  </link>
    # FR_hip_joint_fixed
  <joint name="FR_hip_fixed" type="fixed">
    <origin xyz="0 0.05 0" rpy="0 0 0" />
    <parent link="FR_hip" />
    <child link="FR_thigh_shoulder" />
  </joint>
# FR_thigh_shoulder
  <link name="FR_thigh_shoulder">
  # FR_thigh_shoulder_collision
    <!-- <collision>
      <origin rpy="1.57079632679 0 0" xyz="0 0 0"/>
      <geometry>
        <cylinder length="0.032" radius="0.041"/>
      </geometry>
    </collision> -->
  </link>
# FR_thigh_joint  
  <joint name="FR_thigh_joint" type="revolute">
    <origin xyz="0.024241 0.03725 0.00066796" rpy="0 0 0" />
    <parent link="FR_hip" />
    <child link="FR_thigh" />
    <axis xyz="1 0 0" />
    <dynamics damping="0" friction="0"/>
    <limit effort="20" lower="-1.0471975511" upper="1.0471975511" velocity="52.4" />
  </joint>  
# FR_thigh  
  <link name="FR_thigh">
  # FR_thigh_visual
    <visual>
      <origin xyz="0 0 0" rpy="0 0 0" />
      <geometry>
        <mesh filename="../meshes/FR_thigh.stl" scale="1 1 1"/>
      </geometry>
      <material name=""/>
    </visual>
  # FR_thigh_collision
    <collision>
      <origin xyz="0 0 0" rpy="0 0 0" />
      <geometry>
        <mesh filename="../meshes/FR_thigh.stl" scale="1 1 1"/>
      </geometry>
    </collision>
  # FR_thigh_inertial
    <inertial>
      <origin xyz="0.015177 -0.041543 -0.030122" rpy="0 0 0" />
      <mass value="0.062952" />
      <inertia ixx="0.00010733" ixy="1.7414E-06" ixz="1.3109E-06" iyy="4.0684E-05" iyz="-4.8127E-05" izz="7.0872E-05" />
    </inertial>
  </link>
# FR_calf_joint  
  <joint name="FR_calf_joint" type="revolute">
    <origin xyz="0.016452 -0.096698 -0.070633" rpy="0 0 0" />
    <parent link="FR_thigh" />
    <child link="FR_calf" />
    <axis xyz="1 0 0" />
    <dynamics damping="0" friction="0"/>
    <limit effort="20" lower="-1.7471975511" upper="0.8471975511" velocity="52.4" />
  </joint>
# FR_calf  
  <link name="FR_calf">
  # FR_visual
    <visual>
      <origin xyz="0 0 0" rpy="0 0 0" />
      <geometry> 
        <mesh filename="../meshes/FR_calf.stl" scale="1 1 1"/>
      </geometry>
      <material name=""/> 
    </visual>
  # FR_collision
    <collision>
      <origin xyz="0 0 0" rpy="0 0 0" />
      <geometry> 
        <mesh filename="../meshes/FR_calf.stl" scale="1 1 1"/>
      </geometry>
    </collision>
  # FR_inertial
    <inertial>
      <origin xyz="0.00075507 0.03885 -0.027402" rpy="0 0 0" />
      <mass value="0.014405" />
      <inertia ixx="1.3843E-05" ixy="-1.7178E-07" ixz="1.2445E-07" iyy="4.7137E-06" iyz="6.234E-06" izz="9.3302E-06" />
    </inertial>
  </link>
# FR_foot_fixed_joint  
  <joint name="FR_foot_fixed" type="fixed" dont_collapse="true">
    <origin xyz="0.0018812 0.083071 -0.06827" rpy="0 0 0" />
    <parent link="FR_calf" />
    <child link="FR_foot" />
    <!-- <axis xyz="0 0 0" /> -->
  </joint>
# FR_foot  
  <link name="FR_foot">
    <visual>
      <origin xyz="0 0 0" rpy="0 0 0" />
      <geometry> 
        <mesh filename="../meshes/FR_foot.stl" scale="1 1 1"/>
      </geometry>
      <material name=""> 
        <color   rgba="0.29804 0.29804 0.29804 0" />
      </material>
    </visual>
    <collision>
      <origin xyz="0 0 0" rpy="0 0 0" />
      <geometry> 
        <sphere radius='0.012'/>
      </geometry>
    </collision>
    <inertial>
      <mass value="0.0069771" />
      <inertia ixx="3.8802E-07" ixy="1.1398E-10" ixz="-6.7525E-10" iyy="3.8871E-07" iyz="-4.1322E-09" izz="4.1248E-07" />
    </inertial>
  </link>
# FL_hip_joint  
  <joint name="FL_hip_joint" type="revolute">
    <origin xyz="0.051555 -0.06675 0" rpy="0 0 3.1416" />
    <parent link="trunk" />
    <child link="FL_hip" />
    <axis xyz="0 1 0" />
    <dynamics damping="0" friction="0"/>
    <limit effort="20" lower="-1.0471975511" upper="1.0471975511" velocity="52.4" />
  </joint>
# FL_hip
  <link name="FL_hip">
    <visual>
      <origin xyz="0 0 0" rpy="0 0 0" />
      <geometry> 
        <mesh filename="../meshes/FL_hip.stl" scale="1 1 1"/>
      </geometry>
      <material name=""> 
        <color   rgba="0 1 1 1" />
      </material>
    </visual>
    <!-- <collision>
      <origin xyz="0 0 0" rpy="0 0 0" />
      <geometry> 
        <box size='0.061 0.042 0.0204'/> -->
      <!-- </geometry>
    </collision> -->
    <inertial>
      <origin xyz="-0.0030458 0.024513 8.3928E-05" rpy="0 0 0" />
      <mass value="0.2" />
      <inertia ixx="1.9723E-05" ixy="7.0366E-07" ixz="2.6212E-07" iyy="1.5442E-05" iyz="-1.9389E-08" izz="2.9228E-05" />
    </inertial>
  </link>
# FL_hip_joint_fixed
  <joint name="FL_hip_fixed" type="fixed">
    <origin rpy="0 3.141592653589793 -3.141592653589793" xyz="-0.12 -0.08 0"/>
    <parent link="FL_hip"/>
    <child link="FL_thigh_shoulder"/>
  </joint>
  <!-- this link is only for collision -->
# FL_thigh_shoulder
  <link name="FL_thigh_shoulder">
  # FL_thigh_shoulder_collision
    <!-- <collision>
      <origin rpy="1.57079632679 0 0" xyz="0 0 0"/>
      <geometry>
        <cylinder length="0.032" radius="0.041"/>
      </geometry>
    </collision> -->
  </link>  
# FL_thigh_joint
  <joint name="FL_thigh_joint" type="revolute">
    <origin xyz="-0.024241 0.03725 0.00066796" rpy="0 0 0" />
    <parent link="FL_hip" />
    <child link="FL_thigh" />
    <axis xyz="1 0 0" />
    <limit effort="20" lower="-1.0471975511" upper="1.0471975511" velocity="52.4" />
  </joint>
# FL_thigh 
  <link name="FL_thigh">
    <visual>
      <origin xyz="0 0 0" rpy="0 0 0" />
      <geometry> 
        <mesh filename="../meshes/FL_thigh.stl" scale="1 1 1"/>
      </geometry>
      <material name=""> 
        <color   rgba="1 0 1 1" />
      </material>
    </visual>
    <collision>
      <origin xyz="0 0 0" rpy="0 0 0" />
      <geometry> 
        <mesh filename="../meshes/FL_thigh.stl" scale="1 1 1"/>
      </geometry>
    </collision>
    <inertial>
      <origin xyz="-0.015177 -0.041543 -0.030122" rpy="0 0 0" />
      <mass value="0.062952" />
      <inertia ixx="0.00010733" ixy="-1.7414E-06" ixz="-1.3109E-06" iyy="4.0684E-05" iyz="-4.8127E-05" izz="7.0872E-05" />
    </inertial>
  </link>
# FL_calf_joint  
  <joint name="FL_calf_joint" type="revolute">
    <origin xyz="-0.016452 -0.096698 -0.070633" rpy="0 0 0" />
    <parent link="FL_thigh" />
    <child link="FL_calf" />
    <axis xyz="1 0 0" />
    <dynamics damping="0" friction="0"/>
    <limit effort="20" lower="-1.7471975511" upper="0.8471975511" velocity="52.4" />
  </joint>
# FL_calf  
  <link name="FL_calf">
    <visual>
      <origin xyz="0 0 0" rpy="0 0 0" />
      <geometry> 
        <mesh filename="../meshes/FL_calf.stl" scale="1 1 1"/>
      </geometry>
      <material name=""> 
        <color   rgba="1 1 0 1" />
      </material>
    </visual>
    <collision>
      <origin xyz="0 0 0" rpy="0 0 0" />
      <geometry> 
        <mesh filename="../meshes/FL_calf.stl" scale="1 1 1"/>
      </geometry>
    </collision>
    <inertial>
      <origin xyz="-0.00075507 0.03885 -0.027402" rpy="0 0 0" />
      <mass value="0.014405" />
      <inertia ixx="1.3843E-05" ixy="1.7178E-07" ixz="-1.2445E-07" iyy="4.7137E-06" iyz="6.234E-06" izz="9.3302E-06" />
    </inertial>
  </link>
# FL_foot_fixed_joint  
  <joint name="FL_foot_fixed" type="fixed" dont_collapse="true">
    <origin xyz="-0.0018812 0.083071 -0.06827" rpy="0 0 0" />
    <parent link="FL_calf" />
    <child link="FL_foot" />
  </joint>
# FL_foot  
  <link name="FL_foot">
    <visual>
      <origin xyz="0 0 0" rpy="0 0 0" />
      <geometry> 
        <mesh filename="../meshes/FL_foot.stl" scale="1 1 1"/>
      </geometry>
      <material name=""> 
        <color   rgba="0.29804 0.29804 0.29804 0" />
      </material>
    </visual>
    <collision>
      <origin xyz="0 0 0" rpy="0 0 0" />
      <geometry> 
        <sphere radius='0.012'/>
      </geometry>
    </collision>
    <inertial>
      <mass value="0.0069771" />
      <inertia ixx="3.8802E-07" ixy="-1.14E-10" ixz="6.7524E-10" iyy="3.8871E-07" iyz="-4.1322E-09" izz="4.1248E-07" />
    </inertial>
  </link>
# RR_hip_joint  
  <joint name="RR_hip_joint" type="revolute">
    <origin xyz="-0.05 0.06675 0" rpy="0 0 3.1416" />
    <parent link="trunk" />
    <child link="RR_hip" />
    <axis xyz="0 -1 0" />
    <dynamics damping="0" friction="0"/>    
    <limit effort="20" lower="-1.0471975511" upper="1.0471975511" velocity="52.4" />
  </joint>
# RR_hip
  <link name="RR_hip">
    <visual>
      <origin xyz="0 0 0" rpy="0 0 0" />
      <geometry> 
        <mesh filename="../meshes/RR_hip.stl" scale="1 1 1"/>
      </geometry>
      <material name=""> 
        <color   rgba="0 1 1 1" />
      </material>
    </visual>
    <!-- <collision>
      <origin xyz="0 0 0" rpy="0 0 0" />
      <geometry> 
        <box size='0.061 0.042 0.0204'/> -->
      <!-- </geometry>
    </collision> -->
    <inertial>
      <origin xyz="0.0030458 -0.024513 8.3928E-05" rpy="0 0 0" />
      <mass value="0.2" />
      <inertia ixx="1.9723E-05" ixy="7.0366E-07" ixz="-2.6212E-07" iyy="1.5442E-05" iyz="1.9389E-08" izz="2.9228E-05" />
    </inertial>
  </link>
# RR_hip_joint_fixed
  <joint name="RR_hip_fixed" type="fixed">
    <origin rpy="0 3.141592653589793 -3.141592653589793" xyz="-0.12 -0.08 0"/>
    <parent link="RR_hip"/>
    <child link="RR_thigh_shoulder"/>
  </joint>
  <!-- this link is only for collision -->
# RR_thigh_shoulder
  <link name="RR_thigh_shoulder">
  # RR_thigh_shoulder_collision
    <!-- <collision>
      <origin rpy="1.57079632679 0 0" xyz="0 0 0"/>
      <geometry>
        <cylinder length="0.032" radius="0.041"/>
      </geometry>
    </collision> -->
  </link>
# RR_thigh_joint
  <joint name="RR_thigh_joint" type="revolute">
    <origin xyz="0.024241 -0.03725 0.00066796" rpy="0 0 0" />
    <parent link="RR_hip" />
    <child link="RR_thigh" />
    <axis xyz="1 0 0" />
    <limit effort="20" lower="-1.0471975511" upper="1.0471975511" velocity="52.4" />
  </joint>
# RR_thigh  
  <link name="RR_thigh">
    <visual>
      <origin xyz="0 0 0" rpy="0 0 0" />
      <geometry> 
        <mesh filename="../meshes/RR_thigh.stl" scale="1 1 1"/>
      </geometry>
      <material name=""> 
        <color   rgba="1 0 1 1" />
      </material>
    </visual>
    <collision>
      <origin xyz="0 0 0" rpy="0 0 0" />
      <geometry> 
        <mesh filename="../meshes/RR_thigh.stl" scale="1 1 1"/>
      </geometry>
    </collision>
    <inertial>
      <origin xyz="0.015177 -0.041543 -0.030122" rpy="0 0 0" />
      <mass value="0.062952" />
      <inertia ixx="0.00010733" ixy="1.7414E-06" ixz="1.3109E-06" iyy="4.0684E-05" iyz="-4.8127E-05" izz="7.0872E-05" />
    </inertial>
  </link>
# RR_calf_joint  
  <joint name="RR_calf_joint" type="revolute">
    <origin xyz="0.016452 -0.096698 -0.070633" rpy="0 0 0" />
    <parent link="RR_thigh" />
    <child link="RR_calf" />
    <axis xyz="1 0 0" />
    <dynamics damping="0" friction="0"/>
    <limit effort="20" lower="-1.7471975511" upper="0.8471975511" velocity="52.4" />
  </joint>
# RR_calf  
  <link name="RR_calf">
    <visual>
      <origin xyz="0 0 0" rpy="0 0 0" />
      <geometry> 
        <mesh filename="../meshes/RR_calf.stl" scale="1 1 1"/>
      </geometry>
      <material name=""> 
        <color   rgba="1 1 0 1" />
      </material>
    </visual>
    <collision>
      <origin xyz="0 0 0" rpy="0 0 0" />
      <geometry> 
        <mesh filename="../meshes/RR_calf.stl" scale="1 1 1"/>
      </geometry>
    </collision>
    <inertial>
      <origin xyz="0.00075507 0.03885 -0.027402" rpy="0 0 0" />
      <mass value="0.014405" />
      <inertia ixx="1.3843E-05" ixy="-1.7178E-07" ixz="1.2445E-07" iyy="4.7137E-06" iyz="6.234E-06" izz="9.3302E-06" />
    </inertial>
  </link>
# RR_foot_fixed_joint
  <joint name="RR_foot_fixed" type="fixed" dont_collapse="true">
    <origin xyz="0.0018812 0.083071 -0.06827" rpy="0 0 0" />
    <parent link="RR_calf" />
    <child link="RR_foot" />
  </joint>
# RR_foot
  <link name="RR_foot">
    <visual>
      <origin xyz="0 0 0" rpy="0 0 0" />
      <geometry> 
        <mesh filename="../meshes/RR_foot.stl" scale="1 1 1"/>
      </geometry>
      <material name=""> 
        <color   rgba="0.29804 0.29804 0.29804 0" />
      </material>
    </visual>
    <collision>
      <origin xyz="0 0 0" rpy="0 0 0" />
      <geometry> 
        <sphere radius='0.012'/>
      </geometry>
    </collision>
    <inertial>
      <mass value="0.0069771" />
      <inertia ixx="3.8802E-07" ixy="1.1398E-10" ixz="-6.7525E-10" iyy="3.8871E-07" iyz="-4.1322E-09" izz="4.1248E-07" />
    </inertial>
  </link>
# RL_hip_joint  
  <joint name="RL_hip_joint" type="revolute">
    <origin xyz="0.051555 0.06675 0" rpy="0 0 3.1416" />
    <parent link="trunk" />
    <child link="RL_hip" />
    <axis xyz="0 -1 0" />
    <dynamics damping="0" friction="0"/>
    <limit effort="20" lower="-1.0471975511" upper="1.0471975511" velocity="52.4" />
  </joint>
# RL_hip  
  <link name="RL_hip">
    <visual>
      <origin xyz="0 0 0" rpy="0 0 0" />
      <geometry> 
        <mesh filename="../meshes/RL_hip.stl" scale="1 1 1"/>
      </geometry>
      <material name=""> 
        <color   rgba="0 1 1 1" />
      </material>
    </visual>
    <!-- <collision>
      <origin xyz="0 0 0" rpy="0 0 0" />
      <geometry> 
        <box size='0.061 0.042 0.0204'/> -->
      <!-- </geometry>
    </collision> -->
    <inertial>
      <origin xyz="-0.0030458 -0.024513 8.3928E-05" rpy="0 0 0" />
      <mass value="0.2" />
      <inertia ixx="1.9723E-05" ixy="-7.0366E-07" ixz="2.6212E-07" iyy="1.5442E-05" iyz="1.9389E-08" izz="2.9228E-05" />
    </inertial>
  </link>
# RL_hip_fixed  
  <joint name="RL_hip_fixed" type="fixed">
    <origin rpy="0 0 0" xyz="0 0.081 0"/>
    <parent link="RL_hip"/>
    <child link="RL_thigh_shoulder"/>
  </joint>
  <!-- this link is only for collision -->
  <link name="RL_thigh_shoulder">
    <!-- <collision>
      <origin rpy="1.57079632679 0 0" xyz="0 0 0"/>
      <geometry>
        <cylinder length="0.032" radius="0.041"/>
      </geometry>
    </collision> -->
  </link>
# RL_thigh_joint
  <joint name="RL_thigh_joint" type="revolute">
    <origin xyz="-0.024241 -0.03725 0.00066796" rpy="0 0 0" />
    <parent link="RL_hip" />
    <child link="RL_thigh" />
    <axis xyz="1 0 0" />
    <dynamics damping="0" friction="0"/>
    <limit effort="20" lower="-1.0471975511" upper="1.0471975511" velocity="52.4" />
  </joint>
# RL_thigh  
  <link name="RL_thigh">
    <visual>
      <origin xyz="0 0 0" rpy="0 0 0" />
      <geometry> 
        <mesh filename="../meshes/RL_thigh.stl" scale="1 1 1"/>
      </geometry>
      <material name=""> 
        <color   rgba="1 0 1 1" />
      </material>
    </visual>
    <collision>
      <origin xyz="0 0 0" rpy="0 0 0" />
      <geometry> 
        <mesh filename="../meshes/RL_thigh.stl" scale="1 1 1"/>
      </geometry>
    </collision>
    <inertial>
      <origin xyz="-0.015177 -0.041543 -0.030122" rpy="0 0 0" />
      <mass value="0.062952" />
      <inertia ixx="0.00010733" ixy="-1.7414E-06" ixz="-1.3109E-06" iyy="4.0684E-05" iyz="-4.8127E-05" izz="7.0872E-05" />
    </inertial>
  </link>
# RL_calf_joint  
  <joint name="RL_calf_joint" type="revolute">
    <origin xyz="-0.016452 -0.092698 -0.070633" rpy="0 0 0" />
    <parent link="RL_thigh" />
    <child link="RL_calf" />
    <axis xyz="1 0 0" />
    <dynamics damping="0" friction="0"/>
    <limit effort="20" lower="-1.7471975511" upper="0.8471975511" velocity="52.4" />
  </joint>
# RL_calf  
  <link name="RL_calf">
    <visual>
      <origin xyz="0 0 0" rpy="0 0 0" />
      <geometry> 
        <mesh filename="../meshes/RL_calf.stl" scale="1 1 1"/>
      </geometry>
      <material name=""> 
        <color   rgba="1 1 0 1" />
      </material>
    </visual>
    <collision>
      <origin xyz="0 0 0" rpy="0 0 0" />
      <geometry> 
        <mesh filename="../meshes/RL_calf.stl" scale="1 1 1"/>
      </geometry>
    </collision>
    <inertial>
      <origin xyz="-0.00075507 0.03485 -0.027402" rpy="0 0 0" />
      <mass value="0.014405" />
      <inertia ixx="1.3843E-05" ixy="1.7178E-07" ixz="-1.2445E-07" iyy="4.7137E-06" iyz="6.234E-06" izz="9.3302E-06" />
    </inertial>
  </link>
# RL_foot_fixed_joint
  <joint name="RL_foot_fixed" type="fixed" dont_collapse="true">
    <origin xyz="-0.0018812 0.079071 -0.06827" rpy="0 0 0" />
    <parent link="RL_calf" />
    <child link="RL_foot" />
  </joint>
# RL_foot
  <link name="RL_foot">
    <visual>
      <origin xyz="0 0 0" rpy="0 0 0" />
      <geometry> 
        <mesh filename="../meshes/RL_foot.stl" scale="1 1 1"/>
      </geometry>
      <material name=""> 
        <color   rgba="0.29804 0.29804 0.29804 0" />
      </material>
    </visual>
    <collision>
      <origin xyz="0 0 0" rpy="0 0 0" />
      <geometry> 
        <sphere radius='0.012'/>
      </geometry>
    </collision>
    <inertial>
      <mass value="0.0069771" />
      <inertia ixx="3.8802E-07" ixy="-1.14E-10" ixz="6.7524E-10" iyy="3.8871E-07" iyz="-4.1322E-09" izz="4.1248E-07" />
    </inertial>
  </link>
</robot>